Watching for file changes with StatReloader
Not Found: /
[17/Aug/2020 10:34:47] "GET / HTTP/1.1" 404 2358
Not Found: /
[17/Aug/2020 10:35:01] "GET / HTTP/1.1" 404 2358
Not Found: /
[17/Aug/2020 10:35:02] "GET / HTTP/1.1" 404 2358
Not Found: /
[17/Aug/2020 10:35:03] "GET / HTTP/1.1" 404 2358
Not Found: /api/auth/users
[17/Aug/2020 12:07:28] "POST /api/auth/users HTTP/1.1" 404 2656
Internal Server Error: /auth/users
Traceback (most recent call last):
  File "/home/nick/Bad_drivers/Bad_drivers/env/lib/python3.6/site-packages/django/core/handlers/exception.py", line 47, in inner
    response = get_response(request)
  File "/home/nick/Bad_drivers/Bad_drivers/env/lib/python3.6/site-packages/django/utils/deprecation.py", line 113, in __call__
    response = self.process_request(request)
  File "/home/nick/Bad_drivers/Bad_drivers/env/lib/python3.6/site-packages/django/middleware/common.py", line 54, in process_request
    path = self.get_full_path_with_slash(request)
  File "/home/nick/Bad_drivers/Bad_drivers/env/lib/python3.6/site-packages/django/middleware/common.py", line 94, in get_full_path_with_slash
    'url': request.get_host() + new_path,
RuntimeError: You called this URL via POST, but the URL doesn't end in a slash and you have APPEND_SLASH set. Django can't redirect to the slash URL while maintaining POST data. Change your form to point to 89.223.122.251:8000/auth/users/ (note the trailing slash), or set APPEND_SLASH=False in your Django settings.
[17/Aug/2020 12:08:32] "POST /auth/users HTTP/1.1" 500 15345
Internal Server Error: /auth/users
Traceback (most recent call last):
  File "/home/nick/Bad_drivers/Bad_drivers/env/lib/python3.6/site-packages/django/core/handlers/exception.py", line 47, in inner
    response = get_response(request)
  File "/home/nick/Bad_drivers/Bad_drivers/env/lib/python3.6/site-packages/django/utils/deprecation.py", line 113, in __call__
    response = self.process_request(request)
  File "/home/nick/Bad_drivers/Bad_drivers/env/lib/python3.6/site-packages/django/middleware/common.py", line 54, in process_request
    path = self.get_full_path_with_slash(request)
  File "/home/nick/Bad_drivers/Bad_drivers/env/lib/python3.6/site-packages/django/middleware/common.py", line 94, in get_full_path_with_slash
    'url': request.get_host() + new_path,
RuntimeError: You called this URL via POST, but the URL doesn't end in a slash and you have APPEND_SLASH set. Django can't redirect to the slash URL while maintaining POST data. Change your form to point to 89.223.122.251:8000/auth/users/ (note the trailing slash), or set APPEND_SLASH=False in your Django settings.
[17/Aug/2020 12:14:25] "POST /auth/users HTTP/1.1" 500 15314
Not Found: /
[17/Aug/2020 12:14:37] "GET / HTTP/1.1" 404 2358
Not Found: /favicon.ico
[17/Aug/2020 12:14:37] "GET /favicon.ico HTTP/1.1" 404 2409
Not Found: /api
[17/Aug/2020 12:14:44] "GET /api HTTP/1.1" 404 2385
Not Found: /api/
[17/Aug/2020 12:14:47] "GET /api/ HTTP/1.1" 404 2625
Not Found: /registration/
[17/Aug/2020 12:15:36] "GET /registration/ HTTP/1.1" 404 2826
Not Found: /фгер
[17/Aug/2020 12:16:55] "GET /%D1%84%D0%B3%D0%B5%D1%80 HTTP/1.1" 404 2416
[17/Aug/2020 12:17:00] "GET /auth HTTP/1.1" 301 0
[17/Aug/2020 12:17:00] "GET /auth/ HTTP/1.1" 200 5319
[17/Aug/2020 12:17:00] "GET /static/rest_framework/css/bootstrap-tweaks.css HTTP/1.1" 200 3385
[17/Aug/2020 12:17:00] "GET /static/rest_framework/css/prettify.css HTTP/1.1" 200 817
[17/Aug/2020 12:17:00] "GET /static/rest_framework/css/default.css HTTP/1.1" 200 1131
[17/Aug/2020 12:17:00] "GET /static/rest_framework/js/ajax-form.js HTTP/1.1" 200 3597
[17/Aug/2020 12:17:00] "GET /static/rest_framework/css/bootstrap.min.css HTTP/1.1" 200 121457
[17/Aug/2020 12:17:00] "GET /static/rest_framework/js/csrf.js HTTP/1.1" 200 1719
[17/Aug/2020 12:17:00] "GET /static/rest_framework/js/jquery-3.4.1.min.js HTTP/1.1" 200 88145
[17/Aug/2020 12:17:00] "GET /static/rest_framework/js/bootstrap.min.js HTTP/1.1" 200 39680
[17/Aug/2020 12:17:00] "GET /static/rest_framework/js/prettify-min.js HTTP/1.1" 200 13632
[17/Aug/2020 12:17:00] "GET /static/rest_framework/js/default.js HTTP/1.1" 200 1268
[17/Aug/2020 12:17:00] "GET /static/rest_framework/img/grid.png HTTP/1.1" 200 1458
Not Found: /auth/me
[17/Aug/2020 12:17:06] "GET /auth/me HTTP/1.1" 404 7852
Bad Request: /auth/users/
[17/Aug/2020 12:39:34] "POST /auth/users/ HTTP/1.1" 400 61
Bad Request: /auth/users/
[17/Aug/2020 12:41:17] "POST /auth/users/ HTTP/1.1" 400 61
[17/Aug/2020 12:41:53] "POST /auth/users/ HTTP/1.1" 201 59
Bad Request: /auth/users/
[17/Aug/2020 12:43:12] "POST /auth/users/ HTTP/1.1" 400 58
[17/Aug/2020 12:44:49] "POST /auth/jwt/create/ HTTP/1.1" 200 438
Not Found: /registration/create-full-profile/
[17/Aug/2020 12:51:39] "POST /registration/create-full-profile/ HTTP/1.1" 404 2887
Unauthorized: /registration/create-full-profile
[17/Aug/2020 12:52:24] "POST /registration/create-full-profile HTTP/1.1" 401 183
[17/Aug/2020 12:59:00] "POST /auth/jwt/create/ HTTP/1.1" 200 438
[17/Aug/2020 13:01:48] "POST /auth/jwt/create/ HTTP/1.1" 200 438
[17/Aug/2020 13:03:34] "POST /auth/jwt/create/ HTTP/1.1" 200 438
Bad Request: /auth/jwt/create/
[17/Aug/2020 13:03:35] "POST /auth/jwt/create/ HTTP/1.1" 400 79
[17/Aug/2020 13:05:32] "POST /auth/jwt/create/ HTTP/1.1" 200 438
Bad Request: /auth/jwt/create/
[17/Aug/2020 13:05:32] "POST /auth/jwt/create/ HTTP/1.1" 400 79
[17/Aug/2020 13:06:36] "POST /auth/jwt/create/ HTTP/1.1" 200 438
Bad Request: /auth/jwt/create/
[17/Aug/2020 13:06:36] "POST /auth/jwt/create/ HTTP/1.1" 400 40
[17/Aug/2020 13:06:51] "POST /auth/jwt/create/ HTTP/1.1" 200 438
[17/Aug/2020 13:06:51] "POST /auth/jwt/create/ HTTP/1.1" 200 438
[17/Aug/2020 13:08:25] "POST /auth/jwt/create/ HTTP/1.1" 200 438
[17/Aug/2020 13:08:26] "POST /registration/create-full-profile HTTP/1.1" 201 189
[17/Aug/2020 14:18:23] "POST /auth/jwt/create/ HTTP/1.1" 200 438
Internal Server Error: /registration/get-profile
Traceback (most recent call last):
  File "/home/nick/Bad_drivers/Bad_drivers/env/lib/python3.6/site-packages/django/db/backends/utils.py", line 84, in _execute
    return self.cursor.execute(sql, params)
psycopg2.errors.NotNullViolation: null value in column "user_email" violates not-null constraint
DETAIL:  Failing row contains (2, 2, 0, 0, 0, 0, null, null, null).


The above exception was the direct cause of the following exception:

Traceback (most recent call last):
  File "/home/nick/Bad_drivers/Bad_drivers/env/lib/python3.6/site-packages/django/core/handlers/exception.py", line 47, in inner
    response = get_response(request)
  File "/home/nick/Bad_drivers/Bad_drivers/env/lib/python3.6/site-packages/django/core/handlers/base.py", line 179, in _get_response
    response = wrapped_callback(request, *callback_args, **callback_kwargs)
  File "/home/nick/Bad_drivers/Bad_drivers/env/lib/python3.6/site-packages/django/views/decorators/csrf.py", line 54, in wrapped_view
    return view_func(*args, **kwargs)
  File "/home/nick/Bad_drivers/Bad_drivers/env/lib/python3.6/site-packages/django/views/generic/base.py", line 73, in view
    return self.dispatch(request, *args, **kwargs)
  File "/home/nick/Bad_drivers/Bad_drivers/env/lib/python3.6/site-packages/rest_framework/views.py", line 505, in dispatch
    response = self.handle_exception(exc)
  File "/home/nick/Bad_drivers/Bad_drivers/env/lib/python3.6/site-packages/rest_framework/views.py", line 465, in handle_exception
    self.raise_uncaught_exception(exc)
  File "/home/nick/Bad_drivers/Bad_drivers/env/lib/python3.6/site-packages/rest_framework/views.py", line 476, in raise_uncaught_exception
    raise exc
  File "/home/nick/Bad_drivers/Bad_drivers/env/lib/python3.6/site-packages/rest_framework/views.py", line 502, in dispatch
    response = handler(request, *args, **kwargs)
  File "/home/nick/Bad_drivers/Bad_drivers/env/lib/python3.6/site-packages/rest_framework/generics.py", line 242, in post
    return self.create(request, *args, **kwargs)
  File "/home/nick/Bad_drivers/Bad_drivers/env/lib/python3.6/site-packages/rest_framework/mixins.py", line 19, in create
    self.perform_create(serializer)
  File "/home/nick/Bad_drivers/Bad_drivers/bad_drivers/registration/views.py", line 29, in perform_create
    serializer.save(user=user)
  File "/home/nick/Bad_drivers/Bad_drivers/env/lib/python3.6/site-packages/rest_framework/serializers.py", line 212, in save
    self.instance = self.create(validated_data)
  File "/home/nick/Bad_drivers/Bad_drivers/env/lib/python3.6/site-packages/rest_framework/serializers.py", line 948, in create
    instance = ModelClass._default_manager.create(**validated_data)
  File "/home/nick/Bad_drivers/Bad_drivers/env/lib/python3.6/site-packages/django/db/models/manager.py", line 85, in manager_method
    return getattr(self.get_queryset(), name)(*args, **kwargs)
  File "/home/nick/Bad_drivers/Bad_drivers/env/lib/python3.6/site-packages/django/db/models/query.py", line 447, in create
    obj.save(force_insert=True, using=self.db)
  File "/home/nick/Bad_drivers/Bad_drivers/env/lib/python3.6/site-packages/django/db/models/base.py", line 751, in save
    force_update=force_update, update_fields=update_fields)
  File "/home/nick/Bad_drivers/Bad_drivers/env/lib/python3.6/site-packages/django/db/models/base.py", line 789, in save_base
    force_update, using, update_fields,
  File "/home/nick/Bad_drivers/Bad_drivers/env/lib/python3.6/site-packages/django/db/models/base.py", line 892, in _save_table
    results = self._do_insert(cls._base_manager, using, fields, returning_fields, raw)
  File "/home/nick/Bad_drivers/Bad_drivers/env/lib/python3.6/site-packages/django/db/models/base.py", line 932, in _do_insert
    using=using, raw=raw,
  File "/home/nick/Bad_drivers/Bad_drivers/env/lib/python3.6/site-packages/django/db/models/manager.py", line 85, in manager_method
    return getattr(self.get_queryset(), name)(*args, **kwargs)
  File "/home/nick/Bad_drivers/Bad_drivers/env/lib/python3.6/site-packages/django/db/models/query.py", line 1249, in _insert
    return query.get_compiler(using=using).execute_sql(returning_fields)
  File "/home/nick/Bad_drivers/Bad_drivers/env/lib/python3.6/site-packages/django/db/models/sql/compiler.py", line 1395, in execute_sql
    cursor.execute(sql, params)
  File "/home/nick/Bad_drivers/Bad_drivers/env/lib/python3.6/site-packages/django/db/backends/utils.py", line 98, in execute
    return super().execute(sql, params)
  File "/home/nick/Bad_drivers/Bad_drivers/env/lib/python3.6/site-packages/django/db/backends/utils.py", line 66, in execute
    return self._execute_with_wrappers(sql, params, many=False, executor=self._execute)
  File "/home/nick/Bad_drivers/Bad_drivers/env/lib/python3.6/site-packages/django/db/backends/utils.py", line 75, in _execute_with_wrappers
    return executor(sql, params, many, context)
  File "/home/nick/Bad_drivers/Bad_drivers/env/lib/python3.6/site-packages/django/db/backends/utils.py", line 84, in _execute
    return self.cursor.execute(sql, params)
  File "/home/nick/Bad_drivers/Bad_drivers/env/lib/python3.6/site-packages/django/db/utils.py", line 90, in __exit__
    raise dj_exc_value.with_traceback(traceback) from exc_value
  File "/home/nick/Bad_drivers/Bad_drivers/env/lib/python3.6/site-packages/django/db/backends/utils.py", line 84, in _execute
    return self.cursor.execute(sql, params)
django.db.utils.IntegrityError: null value in column "user_email" violates not-null constraint
DETAIL:  Failing row contains (2, 2, 0, 0, 0, 0, null, null, null).

[17/Aug/2020 14:18:23] "POST /registration/get-profile HTTP/1.1" 500 19788
[17/Aug/2020 14:19:05] "POST /auth/jwt/create/ HTTP/1.1" 200 438
Not Found: /registration/get-profile/
[17/Aug/2020 14:19:05] "POST /registration/get-profile/ HTTP/1.1" 404 2863
[17/Aug/2020 14:43:23] "POST /auth/jwt/create/ HTTP/1.1" 200 438
Internal Server Error: /registration/get-profile
Traceback (most recent call last):
  File "/home/nick/Bad_drivers/Bad_drivers/env/lib/python3.6/site-packages/django/db/backends/utils.py", line 84, in _execute
    return self.cursor.execute(sql, params)
psycopg2.errors.NotNullViolation: null value in column "user_email" violates not-null constraint
DETAIL:  Failing row contains (3, 2, 0, 0, 0, 0, null, null, null).


The above exception was the direct cause of the following exception:

Traceback (most recent call last):
  File "/home/nick/Bad_drivers/Bad_drivers/env/lib/python3.6/site-packages/django/core/handlers/exception.py", line 47, in inner
    response = get_response(request)
  File "/home/nick/Bad_drivers/Bad_drivers/env/lib/python3.6/site-packages/django/core/handlers/base.py", line 179, in _get_response
    response = wrapped_callback(request, *callback_args, **callback_kwargs)
  File "/home/nick/Bad_drivers/Bad_drivers/env/lib/python3.6/site-packages/django/views/decorators/csrf.py", line 54, in wrapped_view
    return view_func(*args, **kwargs)
  File "/home/nick/Bad_drivers/Bad_drivers/env/lib/python3.6/site-packages/django/views/generic/base.py", line 73, in view
    return self.dispatch(request, *args, **kwargs)
  File "/home/nick/Bad_drivers/Bad_drivers/env/lib/python3.6/site-packages/rest_framework/views.py", line 505, in dispatch
    response = self.handle_exception(exc)
  File "/home/nick/Bad_drivers/Bad_drivers/env/lib/python3.6/site-packages/rest_framework/views.py", line 465, in handle_exception
    self.raise_uncaught_exception(exc)
  File "/home/nick/Bad_drivers/Bad_drivers/env/lib/python3.6/site-packages/rest_framework/views.py", line 476, in raise_uncaught_exception
    raise exc
  File "/home/nick/Bad_drivers/Bad_drivers/env/lib/python3.6/site-packages/rest_framework/views.py", line 502, in dispatch
    response = handler(request, *args, **kwargs)
  File "/home/nick/Bad_drivers/Bad_drivers/env/lib/python3.6/site-packages/rest_framework/generics.py", line 242, in post
    return self.create(request, *args, **kwargs)
  File "/home/nick/Bad_drivers/Bad_drivers/env/lib/python3.6/site-packages/rest_framework/mixins.py", line 19, in create
    self.perform_create(serializer)
  File "/home/nick/Bad_drivers/Bad_drivers/bad_drivers/registration/views.py", line 29, in perform_create
    serializer.save(user=user)
  File "/home/nick/Bad_drivers/Bad_drivers/env/lib/python3.6/site-packages/rest_framework/serializers.py", line 212, in save
    self.instance = self.create(validated_data)
  File "/home/nick/Bad_drivers/Bad_drivers/env/lib/python3.6/site-packages/rest_framework/serializers.py", line 948, in create
    instance = ModelClass._default_manager.create(**validated_data)
  File "/home/nick/Bad_drivers/Bad_drivers/env/lib/python3.6/site-packages/django/db/models/manager.py", line 85, in manager_method
    return getattr(self.get_queryset(), name)(*args, **kwargs)
  File "/home/nick/Bad_drivers/Bad_drivers/env/lib/python3.6/site-packages/django/db/models/query.py", line 447, in create
    obj.save(force_insert=True, using=self.db)
  File "/home/nick/Bad_drivers/Bad_drivers/env/lib/python3.6/site-packages/django/db/models/base.py", line 751, in save
    force_update=force_update, update_fields=update_fields)
  File "/home/nick/Bad_drivers/Bad_drivers/env/lib/python3.6/site-packages/django/db/models/base.py", line 789, in save_base
    force_update, using, update_fields,
  File "/home/nick/Bad_drivers/Bad_drivers/env/lib/python3.6/site-packages/django/db/models/base.py", line 892, in _save_table
    results = self._do_insert(cls._base_manager, using, fields, returning_fields, raw)
  File "/home/nick/Bad_drivers/Bad_drivers/env/lib/python3.6/site-packages/django/db/models/base.py", line 932, in _do_insert
    using=using, raw=raw,
  File "/home/nick/Bad_drivers/Bad_drivers/env/lib/python3.6/site-packages/django/db/models/manager.py", line 85, in manager_method
    return getattr(self.get_queryset(), name)(*args, **kwargs)
  File "/home/nick/Bad_drivers/Bad_drivers/env/lib/python3.6/site-packages/django/db/models/query.py", line 1249, in _insert
    return query.get_compiler(using=using).execute_sql(returning_fields)
  File "/home/nick/Bad_drivers/Bad_drivers/env/lib/python3.6/site-packages/django/db/models/sql/compiler.py", line 1395, in execute_sql
    cursor.execute(sql, params)
  File "/home/nick/Bad_drivers/Bad_drivers/env/lib/python3.6/site-packages/django/db/backends/utils.py", line 98, in execute
    return super().execute(sql, params)
  File "/home/nick/Bad_drivers/Bad_drivers/env/lib/python3.6/site-packages/django/db/backends/utils.py", line 66, in execute
    return self._execute_with_wrappers(sql, params, many=False, executor=self._execute)
  File "/home/nick/Bad_drivers/Bad_drivers/env/lib/python3.6/site-packages/django/db/backends/utils.py", line 75, in _execute_with_wrappers
    return executor(sql, params, many, context)
  File "/home/nick/Bad_drivers/Bad_drivers/env/lib/python3.6/site-packages/django/db/backends/utils.py", line 84, in _execute
    return self.cursor.execute(sql, params)
  File "/home/nick/Bad_drivers/Bad_drivers/env/lib/python3.6/site-packages/django/db/utils.py", line 90, in __exit__
    raise dj_exc_value.with_traceback(traceback) from exc_value
  File "/home/nick/Bad_drivers/Bad_drivers/env/lib/python3.6/site-packages/django/db/backends/utils.py", line 84, in _execute
    return self.cursor.execute(sql, params)
django.db.utils.IntegrityError: null value in column "user_email" violates not-null constraint
DETAIL:  Failing row contains (3, 2, 0, 0, 0, 0, null, null, null).

[17/Aug/2020 14:43:24] "POST /registration/get-profile HTTP/1.1" 500 19788
[17/Aug/2020 14:44:22] "POST /auth/jwt/create/ HTTP/1.1" 200 438
[17/Aug/2020 14:44:22] "GET /registration/get-profile HTTP/1.1" 200 201
[17/Aug/2020 14:45:22] "POST /auth/jwt/create/ HTTP/1.1" 200 438
[17/Aug/2020 14:45:22] "GET /registration/get-profile HTTP/1.1" 200 201
[17/Aug/2020 14:45:52] "POST /auth/jwt/create/ HTTP/1.1" 200 438
[17/Aug/2020 14:45:52] "GET /registration/get-profile HTTP/1.1" 200 201
[17/Aug/2020 14:46:11] "POST /auth/jwt/create/ HTTP/1.1" 200 438
[17/Aug/2020 14:46:11] "GET /registration/get-profile HTTP/1.1" 200 201
[17/Aug/2020 14:46:53] "POST /auth/jwt/create/ HTTP/1.1" 200 438
[17/Aug/2020 14:46:53] "GET /registration/get-profile HTTP/1.1" 200 201
[17/Aug/2020 14:47:20] "POST /auth/jwt/create/ HTTP/1.1" 200 438
[17/Aug/2020 14:47:20] "GET /registration/get-profile HTTP/1.1" 200 201
[17/Aug/2020 14:47:31] "POST /auth/jwt/create/ HTTP/1.1" 200 438
[17/Aug/2020 14:47:31] "GET /registration/get-profile HTTP/1.1" 200 201
[17/Aug/2020 14:50:03] "POST /auth/jwt/create/ HTTP/1.1" 200 438
[17/Aug/2020 14:50:03] "GET /registration/get-profile HTTP/1.1" 200 201
[17/Aug/2020 14:51:36] "POST /auth/jwt/create/ HTTP/1.1" 200 438
[17/Aug/2020 14:51:37] "GET /registration/get-profile HTTP/1.1" 200 201
[17/Aug/2020 14:52:22] "POST /auth/jwt/create/ HTTP/1.1" 200 438
[17/Aug/2020 14:52:22] "GET /registration/get-profile HTTP/1.1" 200 201
[17/Aug/2020 14:52:55] "POST /auth/jwt/create/ HTTP/1.1" 200 438
[17/Aug/2020 14:52:55] "GET /registration/get-profile HTTP/1.1" 200 201
[17/Aug/2020 14:53:25] "POST /auth/jwt/create/ HTTP/1.1" 200 438
[17/Aug/2020 14:53:25] "GET /registration/get-profile HTTP/1.1" 200 201
[17/Aug/2020 14:54:19] "POST /auth/jwt/create/ HTTP/1.1" 200 438
[17/Aug/2020 14:54:19] "GET /registration/get-profile HTTP/1.1" 200 201
[17/Aug/2020 14:54:47] "POST /auth/jwt/create/ HTTP/1.1" 200 438
[17/Aug/2020 14:54:48] "GET /registration/get-profile HTTP/1.1" 200 201
[17/Aug/2020 14:55:17] "POST /auth/jwt/create/ HTTP/1.1" 200 438
[17/Aug/2020 14:55:18] "GET /registration/get-profile HTTP/1.1" 200 201
[17/Aug/2020 14:58:32] "POST /auth/jwt/create/ HTTP/1.1" 200 438
[17/Aug/2020 14:58:32] "GET /registration/get-profile HTTP/1.1" 200 201
[17/Aug/2020 15:00:09] "POST /auth/jwt/create/ HTTP/1.1" 200 438
[17/Aug/2020 15:00:09] "GET /registration/get-profile HTTP/1.1" 200 201
Not Found: /registration/get-profile/
[17/Aug/2020 16:44:45] "POST /registration/get-profile/ HTTP/1.1" 404 2863
Unauthorized: /registration/get-profile
[17/Aug/2020 16:45:01] "POST /registration/get-profile HTTP/1.1" 401 183
[17/Aug/2020 16:45:17] "POST /auth/jwt/create/ HTTP/1.1" 200 438
[17/Aug/2020 16:45:17] "GET /registration/get-profile HTTP/1.1" 200 201
[17/Aug/2020 16:45:50] "GET /registration/get-profile HTTP/1.1" 200 201
/home/nick/Bad_drivers/Bad_drivers/bad_drivers/registration/views.py changed, reloading.
Performing system checks...

System check identified no issues (0 silenced).
August 17, 2020 - 10:34:12
Django version 3.1, using settings 'bad_drivers.settings'
Starting development server at http://0.0.0.0:8000/
Quit the server with CONTROL-C.
Watching for file changes with StatReloader
[17/Aug/2020 16:47:18] "GET /registration/get-profile HTTP/1.1" 200 166
[17/Aug/2020 16:48:06] "POST /auth/jwt/create/ HTTP/1.1" 200 438
[17/Aug/2020 16:48:06] "GET /registration/get-profile HTTP/1.1" 200 166
/home/nick/Bad_drivers/Bad_drivers/bad_drivers/registration/views.py changed, reloading.
Performing system checks...

System check identified no issues (0 silenced).
August 17, 2020 - 16:47:15
Django version 3.1, using settings 'bad_drivers.settings'
Starting development server at http://0.0.0.0:8000/
Quit the server with CONTROL-C.
Watching for file changes with StatReloader
/home/nick/Bad_drivers/Bad_drivers/bad_drivers/registration/views.py changed, reloading.
Performing system checks...

System check identified no issues (0 silenced).
August 17, 2020 - 17:51:49
Django version 3.1, using settings 'bad_drivers.settings'
Starting development server at http://0.0.0.0:8000/
Quit the server with CONTROL-C.
Watching for file changes with StatReloader
Bad Request: /auth/users/
[17/Aug/2020 19:00:34] "POST /auth/users/ HTTP/1.1" 400 45
Bad Request: /auth/jwt/create/
[17/Aug/2020 19:00:34] "POST /auth/jwt/create/ HTTP/1.1" 400 45
Unauthorized: /registration/create-full-profile
[17/Aug/2020 19:00:35] "POST /registration/create-full-profile HTTP/1.1" 401 107
Unauthorized: /auth/jwt/create/
[17/Aug/2020 19:02:26] "POST /auth/jwt/create/ HTTP/1.1" 401 63
Unauthorized: /registration/get-profile
[17/Aug/2020 19:02:26] "GET /registration/get-profile HTTP/1.1" 401 107
Not Found: /
[17/Aug/2020 23:24:55] "GET / HTTP/1.1" 404 2358
Bad Request: /auth/users/
[18/Aug/2020 04:55:51] "POST /auth/users/ HTTP/1.1" 400 86
Bad Request: /auth/jwt/create/
[18/Aug/2020 04:55:51] "POST /auth/jwt/create/ HTTP/1.1" 400 45
Unauthorized: /registration/create-full-profile
[18/Aug/2020 04:55:52] "POST /registration/create-full-profile HTTP/1.1" 401 107
Bad Request: /auth/users/
[18/Aug/2020 05:02:50] "POST /auth/users/ HTTP/1.1" 400 45
Bad Request: /auth/jwt/create/
[18/Aug/2020 05:02:51] "POST /auth/jwt/create/ HTTP/1.1" 400 45
Unauthorized: /registration/create-full-profile
[18/Aug/2020 05:02:51] "POST /registration/create-full-profile HTTP/1.1" 401 107
Bad Request: /auth/users/
[18/Aug/2020 05:10:29] "POST /auth/users/ HTTP/1.1" 400 45
Bad Request: /auth/jwt/create/
[18/Aug/2020 05:10:30] "POST /auth/jwt/create/ HTTP/1.1" 400 45
Unauthorized: /registration/create-full-profile
[18/Aug/2020 05:10:30] "GET /registration/create-full-profile?user_name=&user_real_name=NiHui&user_email=sdjk%40mail.ru&recieved_reports=0&send_reports=0&decline_reports=0&processing_reports=0 HTTP/1.1" 401 107
Bad Request: /auth/users/
[18/Aug/2020 05:12:33] "POST /auth/users/ HTTP/1.1" 400 45
Bad Request: /auth/jwt/create/
[18/Aug/2020 05:12:33] "POST /auth/jwt/create/ HTTP/1.1" 400 45
Unauthorized: /registration/create-full-profile
[18/Aug/2020 05:12:33] "GET /registration/create-full-profile?user_name=&user_real_name=NiHui&user_email=sdjk%40mail.ru&recieved_reports=0&send_reports=0&decline_reports=0&processing_reports=0 HTTP/1.1" 401 107
Not Found: /
[18/Aug/2020 05:15:47] "GET / HTTP/1.1" 404 2358
[18/Aug/2020 05:17:39] "POST /auth/users/ HTTP/1.1" 201 51
[18/Aug/2020 05:17:40] "POST /auth/jwt/create/ HTTP/1.1" 200 438
[18/Aug/2020 05:17:40] "GET /registration/create-full-profile?user_name=Test4&user_real_name=NiHui&user_email=test4%40mail.ru&recieved_reports=0&send_reports=0&decline_reports=0&processing_reports=0 HTTP/1.1" 200 191
[18/Aug/2020 05:24:09] "POST /auth/users/ HTTP/1.1" 201 51
[18/Aug/2020 05:24:09] "POST /auth/jwt/create/ HTTP/1.1" 200 438
[18/Aug/2020 05:24:09] "GET /registration/create-full-profile?user_name=Test5&user_real_name=NiHui&user_email=test4%40mail.ru&recieved_reports=0&send_reports=0&decline_reports=0&processing_reports=0 HTTP/1.1" 200 191
Bad Request: /auth/users/
[18/Aug/2020 05:29:20] "POST /auth/users/ HTTP/1.1" 400 58
Unauthorized: /auth/jwt/create/
[18/Aug/2020 05:29:21] "POST /auth/jwt/create/ HTTP/1.1" 401 63
Unauthorized: /registration/create-full-profile
[18/Aug/2020 05:29:22] "GET /registration/create-full-profile?user_name=Tasuke&user_real_name=NiHui&user_email=dsgjn%40mail.ru&recieved_reports=0&send_reports=0&decline_reports=0&processing_reports=0 HTTP/1.1" 401 107
Bad Request: /auth/users/
[18/Aug/2020 05:29:51] "POST /auth/users/ HTTP/1.1" 400 58
Unauthorized: /auth/jwt/create/
[18/Aug/2020 05:29:52] "POST /auth/jwt/create/ HTTP/1.1" 401 63
Unauthorized: /registration/create-full-profile
[18/Aug/2020 05:29:52] "GET /registration/create-full-profile?user_name=Tasuke&user_real_name=NiHui&user_email=dsgjn%40mail.ru&recieved_reports=0&send_reports=0&decline_reports=0&processing_reports=0 HTTP/1.1" 401 107
[18/Aug/2020 05:32:24] "POST /auth/users/ HTTP/1.1" 201 52
[18/Aug/2020 05:32:24] "POST /auth/jwt/create/ HTTP/1.1" 200 438
[18/Aug/2020 05:32:25] "GET /registration/create-full-profile?user_name=Tasuk5&user_real_name=NiHui&user_email=dsgjn%40mail.ru&recieved_reports=0&send_reports=0&decline_reports=0&processing_reports=0 HTTP/1.1" 200 191
/home/nick/Bad_drivers/Bad_drivers/bad_drivers/registration/views.py changed, reloading.
Performing system checks...

System check identified no issues (0 silenced).
August 17, 2020 - 17:51:55
Django version 3.1, using settings 'bad_drivers.settings'
Starting development server at http://0.0.0.0:8000/
Quit the server with CONTROL-C.
Watching for file changes with StatReloader
Exception in thread django-main-thread:
Traceback (most recent call last):
  File "/usr/lib/python3.6/threading.py", line 916, in _bootstrap_inner
    self.run()
  File "/usr/lib/python3.6/threading.py", line 864, in run
    self._target(*self._args, **self._kwargs)
  File "/home/nick/Bad_drivers/Bad_drivers/env/lib/python3.6/site-packages/django/utils/autoreload.py", line 53, in wrapper
    fn(*args, **kwargs)
  File "/home/nick/Bad_drivers/Bad_drivers/env/lib/python3.6/site-packages/django/core/management/commands/runserver.py", line 118, in inner_run
    self.check(display_num_errors=True)
  File "/home/nick/Bad_drivers/Bad_drivers/env/lib/python3.6/site-packages/django/core/management/base.py", line 396, in check
    databases=databases,
  File "/home/nick/Bad_drivers/Bad_drivers/env/lib/python3.6/site-packages/django/core/checks/registry.py", line 70, in run_checks
    new_errors = check(app_configs=app_configs, databases=databases)
  File "/home/nick/Bad_drivers/Bad_drivers/env/lib/python3.6/site-packages/django/core/checks/urls.py", line 13, in check_url_config
    return check_resolver(resolver)
  File "/home/nick/Bad_drivers/Bad_drivers/env/lib/python3.6/site-packages/django/core/checks/urls.py", line 23, in check_resolver
    return check_method()
  File "/home/nick/Bad_drivers/Bad_drivers/env/lib/python3.6/site-packages/django/urls/resolvers.py", line 408, in check
    for pattern in self.url_patterns:
  File "/home/nick/Bad_drivers/Bad_drivers/env/lib/python3.6/site-packages/django/utils/functional.py", line 48, in __get__
    res = instance.__dict__[self.name] = self.func(instance)
  File "/home/nick/Bad_drivers/Bad_drivers/env/lib/python3.6/site-packages/django/urls/resolvers.py", line 589, in url_patterns
    patterns = getattr(self.urlconf_module, "urlpatterns", self.urlconf_module)
  File "/home/nick/Bad_drivers/Bad_drivers/env/lib/python3.6/site-packages/django/utils/functional.py", line 48, in __get__
    res = instance.__dict__[self.name] = self.func(instance)
  File "/home/nick/Bad_drivers/Bad_drivers/env/lib/python3.6/site-packages/django/urls/resolvers.py", line 582, in urlconf_module
    return import_module(self.urlconf_name)
  File "/usr/lib/python3.6/importlib/__init__.py", line 126, in import_module
    return _bootstrap._gcd_import(name[level:], package, level)
  File "<frozen importlib._bootstrap>", line 994, in _gcd_import
  File "<frozen importlib._bootstrap>", line 971, in _find_and_load
  File "<frozen importlib._bootstrap>", line 955, in _find_and_load_unlocked
  File "<frozen importlib._bootstrap>", line 665, in _load_unlocked
  File "<frozen importlib._bootstrap_external>", line 678, in exec_module
  File "<frozen importlib._bootstrap>", line 219, in _call_with_frames_removed
  File "/home/nick/Bad_drivers/Bad_drivers/bad_drivers/bad_drivers/urls.py", line 28, in <module>
    path("registration/",include("registration.urls"))
  File "/home/nick/Bad_drivers/Bad_drivers/env/lib/python3.6/site-packages/django/urls/conf.py", line 34, in include
    urlconf_module = import_module(urlconf_module)
  File "/usr/lib/python3.6/importlib/__init__.py", line 126, in import_module
    return _bootstrap._gcd_import(name[level:], package, level)
  File "<frozen importlib._bootstrap>", line 994, in _gcd_import
  File "<frozen importlib._bootstrap>", line 971, in _find_and_load
  File "<frozen importlib._bootstrap>", line 955, in _find_and_load_unlocked
  File "<frozen importlib._bootstrap>", line 665, in _load_unlocked
  File "<frozen importlib._bootstrap_external>", line 678, in exec_module
  File "<frozen importlib._bootstrap>", line 219, in _call_with_frames_removed
  File "/home/nick/Bad_drivers/Bad_drivers/bad_drivers/registration/urls.py", line 4, in <module>
    from .views import UserProfileListCreateView, UserProfileDetailView, UserProfileUpdate
  File "/home/nick/Bad_drivers/Bad_drivers/bad_drivers/registration/views.py", line 21
    def list(self):
                  ^
IndentationError: unindent does not match any outer indentation level

/home/nick/Bad_drivers/Bad_drivers/bad_drivers/registration/views.py changed, reloading.
Performing system checks...

Watching for file changes with StatReloader
Exception in thread django-main-thread:
Traceback (most recent call last):
  File "/usr/lib/python3.6/threading.py", line 916, in _bootstrap_inner
    self.run()
  File "/usr/lib/python3.6/threading.py", line 864, in run
    self._target(*self._args, **self._kwargs)
  File "/home/nick/Bad_drivers/Bad_drivers/env/lib/python3.6/site-packages/django/utils/autoreload.py", line 53, in wrapper
    fn(*args, **kwargs)
  File "/home/nick/Bad_drivers/Bad_drivers/env/lib/python3.6/site-packages/django/core/management/commands/runserver.py", line 118, in inner_run
    self.check(display_num_errors=True)
  File "/home/nick/Bad_drivers/Bad_drivers/env/lib/python3.6/site-packages/django/core/management/base.py", line 396, in check
    databases=databases,
  File "/home/nick/Bad_drivers/Bad_drivers/env/lib/python3.6/site-packages/django/core/checks/registry.py", line 70, in run_checks
    new_errors = check(app_configs=app_configs, databases=databases)
  File "/home/nick/Bad_drivers/Bad_drivers/env/lib/python3.6/site-packages/django/core/checks/urls.py", line 13, in check_url_config
    return check_resolver(resolver)
  File "/home/nick/Bad_drivers/Bad_drivers/env/lib/python3.6/site-packages/django/core/checks/urls.py", line 23, in check_resolver
    return check_method()
  File "/home/nick/Bad_drivers/Bad_drivers/env/lib/python3.6/site-packages/django/urls/resolvers.py", line 408, in check
    for pattern in self.url_patterns:
  File "/home/nick/Bad_drivers/Bad_drivers/env/lib/python3.6/site-packages/django/utils/functional.py", line 48, in __get__
    res = instance.__dict__[self.name] = self.func(instance)
  File "/home/nick/Bad_drivers/Bad_drivers/env/lib/python3.6/site-packages/django/urls/resolvers.py", line 589, in url_patterns
    patterns = getattr(self.urlconf_module, "urlpatterns", self.urlconf_module)
  File "/home/nick/Bad_drivers/Bad_drivers/env/lib/python3.6/site-packages/django/utils/functional.py", line 48, in __get__
    res = instance.__dict__[self.name] = self.func(instance)
  File "/home/nick/Bad_drivers/Bad_drivers/env/lib/python3.6/site-packages/django/urls/resolvers.py", line 582, in urlconf_module
    return import_module(self.urlconf_name)
  File "/usr/lib/python3.6/importlib/__init__.py", line 126, in import_module
    return _bootstrap._gcd_import(name[level:], package, level)
  File "<frozen importlib._bootstrap>", line 994, in _gcd_import
  File "<frozen importlib._bootstrap>", line 971, in _find_and_load
  File "<frozen importlib._bootstrap>", line 955, in _find_and_load_unlocked
  File "<frozen importlib._bootstrap>", line 665, in _load_unlocked
  File "<frozen importlib._bootstrap_external>", line 678, in exec_module
  File "<frozen importlib._bootstrap>", line 219, in _call_with_frames_removed
  File "/home/nick/Bad_drivers/Bad_drivers/bad_drivers/bad_drivers/urls.py", line 28, in <module>
    path("registration/",include("registration.urls"))
  File "/home/nick/Bad_drivers/Bad_drivers/env/lib/python3.6/site-packages/django/urls/conf.py", line 34, in include
    urlconf_module = import_module(urlconf_module)
  File "/usr/lib/python3.6/importlib/__init__.py", line 126, in import_module
    return _bootstrap._gcd_import(name[level:], package, level)
  File "<frozen importlib._bootstrap>", line 994, in _gcd_import
  File "<frozen importlib._bootstrap>", line 971, in _find_and_load
  File "<frozen importlib._bootstrap>", line 955, in _find_and_load_unlocked
  File "<frozen importlib._bootstrap>", line 665, in _load_unlocked
  File "<frozen importlib._bootstrap_external>", line 678, in exec_module
  File "<frozen importlib._bootstrap>", line 219, in _call_with_frames_removed
  File "/home/nick/Bad_drivers/Bad_drivers/bad_drivers/registration/urls.py", line 4, in <module>
    from .views import UserProfileListCreateView, UserProfileDetailView, UserProfileUpdate
  File "/home/nick/Bad_drivers/Bad_drivers/bad_drivers/registration/views.py", line 21
    def list(self):
                  ^
IndentationError: unindent does not match any outer indentation level

/home/nick/Bad_drivers/Bad_drivers/bad_drivers/registration/views.py changed, reloading.
Performing system checks...

Watching for file changes with StatReloader
Exception in thread django-main-thread:
Traceback (most recent call last):
  File "/usr/lib/python3.6/threading.py", line 916, in _bootstrap_inner
    self.run()
  File "/usr/lib/python3.6/threading.py", line 864, in run
    self._target(*self._args, **self._kwargs)
  File "/home/nick/Bad_drivers/Bad_drivers/env/lib/python3.6/site-packages/django/utils/autoreload.py", line 53, in wrapper
    fn(*args, **kwargs)
  File "/home/nick/Bad_drivers/Bad_drivers/env/lib/python3.6/site-packages/django/core/management/commands/runserver.py", line 118, in inner_run
    self.check(display_num_errors=True)
  File "/home/nick/Bad_drivers/Bad_drivers/env/lib/python3.6/site-packages/django/core/management/base.py", line 396, in check
    databases=databases,
  File "/home/nick/Bad_drivers/Bad_drivers/env/lib/python3.6/site-packages/django/core/checks/registry.py", line 70, in run_checks
    new_errors = check(app_configs=app_configs, databases=databases)
  File "/home/nick/Bad_drivers/Bad_drivers/env/lib/python3.6/site-packages/django/core/checks/urls.py", line 13, in check_url_config
    return check_resolver(resolver)
  File "/home/nick/Bad_drivers/Bad_drivers/env/lib/python3.6/site-packages/django/core/checks/urls.py", line 23, in check_resolver
    return check_method()
  File "/home/nick/Bad_drivers/Bad_drivers/env/lib/python3.6/site-packages/django/urls/resolvers.py", line 408, in check
    for pattern in self.url_patterns:
  File "/home/nick/Bad_drivers/Bad_drivers/env/lib/python3.6/site-packages/django/utils/functional.py", line 48, in __get__
    res = instance.__dict__[self.name] = self.func(instance)
  File "/home/nick/Bad_drivers/Bad_drivers/env/lib/python3.6/site-packages/django/urls/resolvers.py", line 589, in url_patterns
    patterns = getattr(self.urlconf_module, "urlpatterns", self.urlconf_module)
  File "/home/nick/Bad_drivers/Bad_drivers/env/lib/python3.6/site-packages/django/utils/functional.py", line 48, in __get__
    res = instance.__dict__[self.name] = self.func(instance)
  File "/home/nick/Bad_drivers/Bad_drivers/env/lib/python3.6/site-packages/django/urls/resolvers.py", line 582, in urlconf_module
    return import_module(self.urlconf_name)
  File "/usr/lib/python3.6/importlib/__init__.py", line 126, in import_module
    return _bootstrap._gcd_import(name[level:], package, level)
  File "<frozen importlib._bootstrap>", line 994, in _gcd_import
  File "<frozen importlib._bootstrap>", line 971, in _find_and_load
  File "<frozen importlib._bootstrap>", line 955, in _find_and_load_unlocked
  File "<frozen importlib._bootstrap>", line 665, in _load_unlocked
  File "<frozen importlib._bootstrap_external>", line 678, in exec_module
  File "<frozen importlib._bootstrap>", line 219, in _call_with_frames_removed
  File "/home/nick/Bad_drivers/Bad_drivers/bad_drivers/bad_drivers/urls.py", line 28, in <module>
    path("registration/",include("registration.urls"))
  File "/home/nick/Bad_drivers/Bad_drivers/env/lib/python3.6/site-packages/django/urls/conf.py", line 34, in include
    urlconf_module = import_module(urlconf_module)
  File "/usr/lib/python3.6/importlib/__init__.py", line 126, in import_module
    return _bootstrap._gcd_import(name[level:], package, level)
  File "<frozen importlib._bootstrap>", line 994, in _gcd_import
  File "<frozen importlib._bootstrap>", line 971, in _find_and_load
  File "<frozen importlib._bootstrap>", line 955, in _find_and_load_unlocked
  File "<frozen importlib._bootstrap>", line 665, in _load_unlocked
  File "<frozen importlib._bootstrap_external>", line 678, in exec_module
  File "<frozen importlib._bootstrap>", line 219, in _call_with_frames_removed
  File "/home/nick/Bad_drivers/Bad_drivers/bad_drivers/registration/urls.py", line 4, in <module>
    from .views import UserProfileListCreateView, UserProfileDetailView, UserProfileUpdate
  File "/home/nick/Bad_drivers/Bad_drivers/bad_drivers/registration/views.py", line 21
    def list(self):
                  ^
IndentationError: unindent does not match any outer indentation level

/home/nick/Bad_drivers/Bad_drivers/bad_drivers/registration/views.py changed, reloading.
Performing system checks...

Watching for file changes with StatReloader
Exception in thread django-main-thread:
Traceback (most recent call last):
  File "/usr/lib/python3.6/threading.py", line 916, in _bootstrap_inner
    self.run()
  File "/usr/lib/python3.6/threading.py", line 864, in run
    self._target(*self._args, **self._kwargs)
  File "/home/nick/Bad_drivers/Bad_drivers/env/lib/python3.6/site-packages/django/utils/autoreload.py", line 53, in wrapper
    fn(*args, **kwargs)
  File "/home/nick/Bad_drivers/Bad_drivers/env/lib/python3.6/site-packages/django/core/management/commands/runserver.py", line 118, in inner_run
    self.check(display_num_errors=True)
  File "/home/nick/Bad_drivers/Bad_drivers/env/lib/python3.6/site-packages/django/core/management/base.py", line 396, in check
    databases=databases,
  File "/home/nick/Bad_drivers/Bad_drivers/env/lib/python3.6/site-packages/django/core/checks/registry.py", line 70, in run_checks
    new_errors = check(app_configs=app_configs, databases=databases)
  File "/home/nick/Bad_drivers/Bad_drivers/env/lib/python3.6/site-packages/django/core/checks/urls.py", line 13, in check_url_config
    return check_resolver(resolver)
  File "/home/nick/Bad_drivers/Bad_drivers/env/lib/python3.6/site-packages/django/core/checks/urls.py", line 23, in check_resolver
    return check_method()
  File "/home/nick/Bad_drivers/Bad_drivers/env/lib/python3.6/site-packages/django/urls/resolvers.py", line 408, in check
    for pattern in self.url_patterns:
  File "/home/nick/Bad_drivers/Bad_drivers/env/lib/python3.6/site-packages/django/utils/functional.py", line 48, in __get__
    res = instance.__dict__[self.name] = self.func(instance)
  File "/home/nick/Bad_drivers/Bad_drivers/env/lib/python3.6/site-packages/django/urls/resolvers.py", line 589, in url_patterns
    patterns = getattr(self.urlconf_module, "urlpatterns", self.urlconf_module)
  File "/home/nick/Bad_drivers/Bad_drivers/env/lib/python3.6/site-packages/django/utils/functional.py", line 48, in __get__
    res = instance.__dict__[self.name] = self.func(instance)
  File "/home/nick/Bad_drivers/Bad_drivers/env/lib/python3.6/site-packages/django/urls/resolvers.py", line 582, in urlconf_module
    return import_module(self.urlconf_name)
  File "/usr/lib/python3.6/importlib/__init__.py", line 126, in import_module
    return _bootstrap._gcd_import(name[level:], package, level)
  File "<frozen importlib._bootstrap>", line 994, in _gcd_import
  File "<frozen importlib._bootstrap>", line 971, in _find_and_load
  File "<frozen importlib._bootstrap>", line 955, in _find_and_load_unlocked
  File "<frozen importlib._bootstrap>", line 665, in _load_unlocked
  File "<frozen importlib._bootstrap_external>", line 678, in exec_module
  File "<frozen importlib._bootstrap>", line 219, in _call_with_frames_removed
  File "/home/nick/Bad_drivers/Bad_drivers/bad_drivers/bad_drivers/urls.py", line 28, in <module>
    path("registration/",include("registration.urls"))
  File "/home/nick/Bad_drivers/Bad_drivers/env/lib/python3.6/site-packages/django/urls/conf.py", line 34, in include
    urlconf_module = import_module(urlconf_module)
  File "/usr/lib/python3.6/importlib/__init__.py", line 126, in import_module
    return _bootstrap._gcd_import(name[level:], package, level)
  File "<frozen importlib._bootstrap>", line 994, in _gcd_import
  File "<frozen importlib._bootstrap>", line 971, in _find_and_load
  File "<frozen importlib._bootstrap>", line 955, in _find_and_load_unlocked
  File "<frozen importlib._bootstrap>", line 665, in _load_unlocked
  File "<frozen importlib._bootstrap_external>", line 678, in exec_module
  File "<frozen importlib._bootstrap>", line 219, in _call_with_frames_removed
  File "/home/nick/Bad_drivers/Bad_drivers/bad_drivers/registration/urls.py", line 4, in <module>
    from .views import UserProfileListCreateView, UserProfileDetailView, UserProfileUpdate
  File "/home/nick/Bad_drivers/Bad_drivers/bad_drivers/registration/views.py", line 21
    def list(self, request):
                           ^
IndentationError: unindent does not match any outer indentation level

/home/nick/Bad_drivers/Bad_drivers/bad_drivers/registration/views.py changed, reloading.
Performing system checks...

Watching for file changes with StatReloader
Exception in thread django-main-thread:
Traceback (most recent call last):
  File "/usr/lib/python3.6/threading.py", line 916, in _bootstrap_inner
    self.run()
  File "/usr/lib/python3.6/threading.py", line 864, in run
    self._target(*self._args, **self._kwargs)
  File "/home/nick/Bad_drivers/Bad_drivers/env/lib/python3.6/site-packages/django/utils/autoreload.py", line 53, in wrapper
    fn(*args, **kwargs)
  File "/home/nick/Bad_drivers/Bad_drivers/env/lib/python3.6/site-packages/django/core/management/commands/runserver.py", line 118, in inner_run
    self.check(display_num_errors=True)
  File "/home/nick/Bad_drivers/Bad_drivers/env/lib/python3.6/site-packages/django/core/management/base.py", line 396, in check
    databases=databases,
  File "/home/nick/Bad_drivers/Bad_drivers/env/lib/python3.6/site-packages/django/core/checks/registry.py", line 70, in run_checks
    new_errors = check(app_configs=app_configs, databases=databases)
  File "/home/nick/Bad_drivers/Bad_drivers/env/lib/python3.6/site-packages/django/core/checks/urls.py", line 13, in check_url_config
    return check_resolver(resolver)
  File "/home/nick/Bad_drivers/Bad_drivers/env/lib/python3.6/site-packages/django/core/checks/urls.py", line 23, in check_resolver
    return check_method()
  File "/home/nick/Bad_drivers/Bad_drivers/env/lib/python3.6/site-packages/django/urls/resolvers.py", line 408, in check
    for pattern in self.url_patterns:
  File "/home/nick/Bad_drivers/Bad_drivers/env/lib/python3.6/site-packages/django/utils/functional.py", line 48, in __get__
    res = instance.__dict__[self.name] = self.func(instance)
  File "/home/nick/Bad_drivers/Bad_drivers/env/lib/python3.6/site-packages/django/urls/resolvers.py", line 589, in url_patterns
    patterns = getattr(self.urlconf_module, "urlpatterns", self.urlconf_module)
  File "/home/nick/Bad_drivers/Bad_drivers/env/lib/python3.6/site-packages/django/utils/functional.py", line 48, in __get__
    res = instance.__dict__[self.name] = self.func(instance)
  File "/home/nick/Bad_drivers/Bad_drivers/env/lib/python3.6/site-packages/django/urls/resolvers.py", line 582, in urlconf_module
    return import_module(self.urlconf_name)
  File "/usr/lib/python3.6/importlib/__init__.py", line 126, in import_module
    return _bootstrap._gcd_import(name[level:], package, level)
  File "<frozen importlib._bootstrap>", line 994, in _gcd_import
  File "<frozen importlib._bootstrap>", line 971, in _find_and_load
  File "<frozen importlib._bootstrap>", line 955, in _find_and_load_unlocked
  File "<frozen importlib._bootstrap>", line 665, in _load_unlocked
  File "<frozen importlib._bootstrap_external>", line 678, in exec_module
  File "<frozen importlib._bootstrap>", line 219, in _call_with_frames_removed
  File "/home/nick/Bad_drivers/Bad_drivers/bad_drivers/bad_drivers/urls.py", line 28, in <module>
    path("registration/",include("registration.urls"))
  File "/home/nick/Bad_drivers/Bad_drivers/env/lib/python3.6/site-packages/django/urls/conf.py", line 34, in include
    urlconf_module = import_module(urlconf_module)
  File "/usr/lib/python3.6/importlib/__init__.py", line 126, in import_module
    return _bootstrap._gcd_import(name[level:], package, level)
  File "<frozen importlib._bootstrap>", line 994, in _gcd_import
  File "<frozen importlib._bootstrap>", line 971, in _find_and_load
  File "<frozen importlib._bootstrap>", line 955, in _find_and_load_unlocked
  File "<frozen importlib._bootstrap>", line 665, in _load_unlocked
  File "<frozen importlib._bootstrap_external>", line 678, in exec_module
  File "<frozen importlib._bootstrap>", line 219, in _call_with_frames_removed
  File "/home/nick/Bad_drivers/Bad_drivers/bad_drivers/registration/urls.py", line 4, in <module>
    from .views import UserProfileListCreateView, UserProfileDetailView, UserProfileUpdate
  File "/home/nick/Bad_drivers/Bad_drivers/bad_drivers/registration/views.py", line 21
    def list(self, request):
                           ^
IndentationError: unindent does not match any outer indentation level

/home/nick/Bad_drivers/Bad_drivers/bad_drivers/registration/views.py changed, reloading.
Performing system checks...

Watching for file changes with StatReloader
Exception in thread django-main-thread:
Traceback (most recent call last):
  File "/usr/lib/python3.6/threading.py", line 916, in _bootstrap_inner
    self.run()
  File "/usr/lib/python3.6/threading.py", line 864, in run
    self._target(*self._args, **self._kwargs)
  File "/home/nick/Bad_drivers/Bad_drivers/env/lib/python3.6/site-packages/django/utils/autoreload.py", line 53, in wrapper
    fn(*args, **kwargs)
  File "/home/nick/Bad_drivers/Bad_drivers/env/lib/python3.6/site-packages/django/core/management/commands/runserver.py", line 118, in inner_run
    self.check(display_num_errors=True)
  File "/home/nick/Bad_drivers/Bad_drivers/env/lib/python3.6/site-packages/django/core/management/base.py", line 396, in check
    databases=databases,
  File "/home/nick/Bad_drivers/Bad_drivers/env/lib/python3.6/site-packages/django/core/checks/registry.py", line 70, in run_checks
    new_errors = check(app_configs=app_configs, databases=databases)
  File "/home/nick/Bad_drivers/Bad_drivers/env/lib/python3.6/site-packages/django/core/checks/urls.py", line 13, in check_url_config
    return check_resolver(resolver)
  File "/home/nick/Bad_drivers/Bad_drivers/env/lib/python3.6/site-packages/django/core/checks/urls.py", line 23, in check_resolver
    return check_method()
  File "/home/nick/Bad_drivers/Bad_drivers/env/lib/python3.6/site-packages/django/urls/resolvers.py", line 408, in check
    for pattern in self.url_patterns:
  File "/home/nick/Bad_drivers/Bad_drivers/env/lib/python3.6/site-packages/django/utils/functional.py", line 48, in __get__
    res = instance.__dict__[self.name] = self.func(instance)
  File "/home/nick/Bad_drivers/Bad_drivers/env/lib/python3.6/site-packages/django/urls/resolvers.py", line 589, in url_patterns
    patterns = getattr(self.urlconf_module, "urlpatterns", self.urlconf_module)
  File "/home/nick/Bad_drivers/Bad_drivers/env/lib/python3.6/site-packages/django/utils/functional.py", line 48, in __get__
    res = instance.__dict__[self.name] = self.func(instance)
  File "/home/nick/Bad_drivers/Bad_drivers/env/lib/python3.6/site-packages/django/urls/resolvers.py", line 582, in urlconf_module
    return import_module(self.urlconf_name)
  File "/usr/lib/python3.6/importlib/__init__.py", line 126, in import_module
    return _bootstrap._gcd_import(name[level:], package, level)
  File "<frozen importlib._bootstrap>", line 994, in _gcd_import
  File "<frozen importlib._bootstrap>", line 971, in _find_and_load
  File "<frozen importlib._bootstrap>", line 955, in _find_and_load_unlocked
  File "<frozen importlib._bootstrap>", line 665, in _load_unlocked
  File "<frozen importlib._bootstrap_external>", line 678, in exec_module
  File "<frozen importlib._bootstrap>", line 219, in _call_with_frames_removed
  File "/home/nick/Bad_drivers/Bad_drivers/bad_drivers/bad_drivers/urls.py", line 28, in <module>
    path("registration/",include("registration.urls"))
  File "/home/nick/Bad_drivers/Bad_drivers/env/lib/python3.6/site-packages/django/urls/conf.py", line 34, in include
    urlconf_module = import_module(urlconf_module)
  File "/usr/lib/python3.6/importlib/__init__.py", line 126, in import_module
    return _bootstrap._gcd_import(name[level:], package, level)
  File "<frozen importlib._bootstrap>", line 994, in _gcd_import
  File "<frozen importlib._bootstrap>", line 971, in _find_and_load
  File "<frozen importlib._bootstrap>", line 955, in _find_and_load_unlocked
  File "<frozen importlib._bootstrap>", line 665, in _load_unlocked
  File "<frozen importlib._bootstrap_external>", line 678, in exec_module
  File "<frozen importlib._bootstrap>", line 219, in _call_with_frames_removed
  File "/home/nick/Bad_drivers/Bad_drivers/bad_drivers/registration/urls.py", line 4, in <module>
    from .views import UserProfileListCreateView, UserProfileDetailView, UserProfileUpdate
  File "/home/nick/Bad_drivers/Bad_drivers/bad_drivers/registration/views.py", line 21
    def list(self, request):
                           ^
IndentationError: unindent does not match any outer indentation level

/home/nick/Bad_drivers/Bad_drivers/bad_drivers/registration/views.py changed, reloading.
Performing system checks...

Watching for file changes with StatReloader
Exception in thread django-main-thread:
Traceback (most recent call last):
  File "/usr/lib/python3.6/threading.py", line 916, in _bootstrap_inner
    self.run()
  File "/usr/lib/python3.6/threading.py", line 864, in run
    self._target(*self._args, **self._kwargs)
  File "/home/nick/Bad_drivers/Bad_drivers/env/lib/python3.6/site-packages/django/utils/autoreload.py", line 53, in wrapper
    fn(*args, **kwargs)
  File "/home/nick/Bad_drivers/Bad_drivers/env/lib/python3.6/site-packages/django/core/management/commands/runserver.py", line 118, in inner_run
    self.check(display_num_errors=True)
  File "/home/nick/Bad_drivers/Bad_drivers/env/lib/python3.6/site-packages/django/core/management/base.py", line 396, in check
    databases=databases,
  File "/home/nick/Bad_drivers/Bad_drivers/env/lib/python3.6/site-packages/django/core/checks/registry.py", line 70, in run_checks
    new_errors = check(app_configs=app_configs, databases=databases)
  File "/home/nick/Bad_drivers/Bad_drivers/env/lib/python3.6/site-packages/django/core/checks/urls.py", line 13, in check_url_config
    return check_resolver(resolver)
  File "/home/nick/Bad_drivers/Bad_drivers/env/lib/python3.6/site-packages/django/core/checks/urls.py", line 23, in check_resolver
    return check_method()
  File "/home/nick/Bad_drivers/Bad_drivers/env/lib/python3.6/site-packages/django/urls/resolvers.py", line 408, in check
    for pattern in self.url_patterns:
  File "/home/nick/Bad_drivers/Bad_drivers/env/lib/python3.6/site-packages/django/utils/functional.py", line 48, in __get__
    res = instance.__dict__[self.name] = self.func(instance)
  File "/home/nick/Bad_drivers/Bad_drivers/env/lib/python3.6/site-packages/django/urls/resolvers.py", line 589, in url_patterns
    patterns = getattr(self.urlconf_module, "urlpatterns", self.urlconf_module)
  File "/home/nick/Bad_drivers/Bad_drivers/env/lib/python3.6/site-packages/django/utils/functional.py", line 48, in __get__
    res = instance.__dict__[self.name] = self.func(instance)
  File "/home/nick/Bad_drivers/Bad_drivers/env/lib/python3.6/site-packages/django/urls/resolvers.py", line 582, in urlconf_module
    return import_module(self.urlconf_name)
  File "/usr/lib/python3.6/importlib/__init__.py", line 126, in import_module
    return _bootstrap._gcd_import(name[level:], package, level)
  File "<frozen importlib._bootstrap>", line 994, in _gcd_import
  File "<frozen importlib._bootstrap>", line 971, in _find_and_load
  File "<frozen importlib._bootstrap>", line 955, in _find_and_load_unlocked
  File "<frozen importlib._bootstrap>", line 665, in _load_unlocked
  File "<frozen importlib._bootstrap_external>", line 678, in exec_module
  File "<frozen importlib._bootstrap>", line 219, in _call_with_frames_removed
  File "/home/nick/Bad_drivers/Bad_drivers/bad_drivers/bad_drivers/urls.py", line 28, in <module>
    path("registration/",include("registration.urls"))
  File "/home/nick/Bad_drivers/Bad_drivers/env/lib/python3.6/site-packages/django/urls/conf.py", line 34, in include
    urlconf_module = import_module(urlconf_module)
  File "/usr/lib/python3.6/importlib/__init__.py", line 126, in import_module
    return _bootstrap._gcd_import(name[level:], package, level)
  File "<frozen importlib._bootstrap>", line 994, in _gcd_import
  File "<frozen importlib._bootstrap>", line 971, in _find_and_load
  File "<frozen importlib._bootstrap>", line 955, in _find_and_load_unlocked
  File "<frozen importlib._bootstrap>", line 665, in _load_unlocked
  File "<frozen importlib._bootstrap_external>", line 678, in exec_module
  File "<frozen importlib._bootstrap>", line 219, in _call_with_frames_removed
  File "/home/nick/Bad_drivers/Bad_drivers/bad_drivers/registration/urls.py", line 4, in <module>
    from .views import UserProfileListCreateView, UserProfileDetailView, UserProfileUpdate
  File "/home/nick/Bad_drivers/Bad_drivers/bad_drivers/registration/views.py", line 21
    def list(self, request):
                           ^
IndentationError: unindent does not match any outer indentation level

/home/nick/Bad_drivers/Bad_drivers/bad_drivers/registration/views.py changed, reloading.
Performing system checks...

Watching for file changes with StatReloader
Exception in thread django-main-thread:
Traceback (most recent call last):
  File "/usr/lib/python3.6/threading.py", line 916, in _bootstrap_inner
    self.run()
  File "/usr/lib/python3.6/threading.py", line 864, in run
    self._target(*self._args, **self._kwargs)
  File "/home/nick/Bad_drivers/Bad_drivers/env/lib/python3.6/site-packages/django/utils/autoreload.py", line 53, in wrapper
    fn(*args, **kwargs)
  File "/home/nick/Bad_drivers/Bad_drivers/env/lib/python3.6/site-packages/django/core/management/commands/runserver.py", line 118, in inner_run
    self.check(display_num_errors=True)
  File "/home/nick/Bad_drivers/Bad_drivers/env/lib/python3.6/site-packages/django/core/management/base.py", line 396, in check
    databases=databases,
  File "/home/nick/Bad_drivers/Bad_drivers/env/lib/python3.6/site-packages/django/core/checks/registry.py", line 70, in run_checks
    new_errors = check(app_configs=app_configs, databases=databases)
  File "/home/nick/Bad_drivers/Bad_drivers/env/lib/python3.6/site-packages/django/core/checks/urls.py", line 13, in check_url_config
    return check_resolver(resolver)
  File "/home/nick/Bad_drivers/Bad_drivers/env/lib/python3.6/site-packages/django/core/checks/urls.py", line 23, in check_resolver
    return check_method()
  File "/home/nick/Bad_drivers/Bad_drivers/env/lib/python3.6/site-packages/django/urls/resolvers.py", line 408, in check
    for pattern in self.url_patterns:
  File "/home/nick/Bad_drivers/Bad_drivers/env/lib/python3.6/site-packages/django/utils/functional.py", line 48, in __get__
    res = instance.__dict__[self.name] = self.func(instance)
  File "/home/nick/Bad_drivers/Bad_drivers/env/lib/python3.6/site-packages/django/urls/resolvers.py", line 589, in url_patterns
    patterns = getattr(self.urlconf_module, "urlpatterns", self.urlconf_module)
  File "/home/nick/Bad_drivers/Bad_drivers/env/lib/python3.6/site-packages/django/utils/functional.py", line 48, in __get__
    res = instance.__dict__[self.name] = self.func(instance)
  File "/home/nick/Bad_drivers/Bad_drivers/env/lib/python3.6/site-packages/django/urls/resolvers.py", line 582, in urlconf_module
    return import_module(self.urlconf_name)
  File "/usr/lib/python3.6/importlib/__init__.py", line 126, in import_module
    return _bootstrap._gcd_import(name[level:], package, level)
  File "<frozen importlib._bootstrap>", line 994, in _gcd_import
  File "<frozen importlib._bootstrap>", line 971, in _find_and_load
  File "<frozen importlib._bootstrap>", line 955, in _find_and_load_unlocked
  File "<frozen importlib._bootstrap>", line 665, in _load_unlocked
  File "<frozen importlib._bootstrap_external>", line 678, in exec_module
  File "<frozen importlib._bootstrap>", line 219, in _call_with_frames_removed
  File "/home/nick/Bad_drivers/Bad_drivers/bad_drivers/bad_drivers/urls.py", line 28, in <module>
    path("registration/",include("registration.urls"))
  File "/home/nick/Bad_drivers/Bad_drivers/env/lib/python3.6/site-packages/django/urls/conf.py", line 34, in include
    urlconf_module = import_module(urlconf_module)
  File "/usr/lib/python3.6/importlib/__init__.py", line 126, in import_module
    return _bootstrap._gcd_import(name[level:], package, level)
  File "<frozen importlib._bootstrap>", line 994, in _gcd_import
  File "<frozen importlib._bootstrap>", line 971, in _find_and_load
  File "<frozen importlib._bootstrap>", line 955, in _find_and_load_unlocked
  File "<frozen importlib._bootstrap>", line 665, in _load_unlocked
  File "<frozen importlib._bootstrap_external>", line 678, in exec_module
  File "<frozen importlib._bootstrap>", line 219, in _call_with_frames_removed
  File "/home/nick/Bad_drivers/Bad_drivers/bad_drivers/registration/urls.py", line 4, in <module>
    from .views import UserProfileListCreateView, UserProfileDetailView, UserProfileUpdate
  File "/home/nick/Bad_drivers/Bad_drivers/bad_drivers/registration/views.py", line 21
    def list(self, request):
                           ^
IndentationError: unindent does not match any outer indentation level

/home/nick/Bad_drivers/Bad_drivers/bad_drivers/registration/views.py changed, reloading.
Performing system checks...

Watching for file changes with StatReloader
Exception in thread django-main-thread:
Traceback (most recent call last):
  File "/usr/lib/python3.6/threading.py", line 916, in _bootstrap_inner
    self.run()
  File "/usr/lib/python3.6/threading.py", line 864, in run
    self._target(*self._args, **self._kwargs)
  File "/home/nick/Bad_drivers/Bad_drivers/env/lib/python3.6/site-packages/django/utils/autoreload.py", line 53, in wrapper
    fn(*args, **kwargs)
  File "/home/nick/Bad_drivers/Bad_drivers/env/lib/python3.6/site-packages/django/core/management/commands/runserver.py", line 118, in inner_run
    self.check(display_num_errors=True)
  File "/home/nick/Bad_drivers/Bad_drivers/env/lib/python3.6/site-packages/django/core/management/base.py", line 396, in check
    databases=databases,
  File "/home/nick/Bad_drivers/Bad_drivers/env/lib/python3.6/site-packages/django/core/checks/registry.py", line 70, in run_checks
    new_errors = check(app_configs=app_configs, databases=databases)
  File "/home/nick/Bad_drivers/Bad_drivers/env/lib/python3.6/site-packages/django/core/checks/urls.py", line 13, in check_url_config
    return check_resolver(resolver)
  File "/home/nick/Bad_drivers/Bad_drivers/env/lib/python3.6/site-packages/django/core/checks/urls.py", line 23, in check_resolver
    return check_method()
  File "/home/nick/Bad_drivers/Bad_drivers/env/lib/python3.6/site-packages/django/urls/resolvers.py", line 408, in check
    for pattern in self.url_patterns:
  File "/home/nick/Bad_drivers/Bad_drivers/env/lib/python3.6/site-packages/django/utils/functional.py", line 48, in __get__
    res = instance.__dict__[self.name] = self.func(instance)
  File "/home/nick/Bad_drivers/Bad_drivers/env/lib/python3.6/site-packages/django/urls/resolvers.py", line 589, in url_patterns
    patterns = getattr(self.urlconf_module, "urlpatterns", self.urlconf_module)
  File "/home/nick/Bad_drivers/Bad_drivers/env/lib/python3.6/site-packages/django/utils/functional.py", line 48, in __get__
    res = instance.__dict__[self.name] = self.func(instance)
  File "/home/nick/Bad_drivers/Bad_drivers/env/lib/python3.6/site-packages/django/urls/resolvers.py", line 582, in urlconf_module
    return import_module(self.urlconf_name)
  File "/usr/lib/python3.6/importlib/__init__.py", line 126, in import_module
    return _bootstrap._gcd_import(name[level:], package, level)
  File "<frozen importlib._bootstrap>", line 994, in _gcd_import
  File "<frozen importlib._bootstrap>", line 971, in _find_and_load
  File "<frozen importlib._bootstrap>", line 955, in _find_and_load_unlocked
  File "<frozen importlib._bootstrap>", line 665, in _load_unlocked
  File "<frozen importlib._bootstrap_external>", line 678, in exec_module
  File "<frozen importlib._bootstrap>", line 219, in _call_with_frames_removed
  File "/home/nick/Bad_drivers/Bad_drivers/bad_drivers/bad_drivers/urls.py", line 28, in <module>
    path("registration/",include("registration.urls"))
  File "/home/nick/Bad_drivers/Bad_drivers/env/lib/python3.6/site-packages/django/urls/conf.py", line 34, in include
    urlconf_module = import_module(urlconf_module)
  File "/usr/lib/python3.6/importlib/__init__.py", line 126, in import_module
    return _bootstrap._gcd_import(name[level:], package, level)
  File "<frozen importlib._bootstrap>", line 994, in _gcd_import
  File "<frozen importlib._bootstrap>", line 971, in _find_and_load
  File "<frozen importlib._bootstrap>", line 955, in _find_and_load_unlocked
  File "<frozen importlib._bootstrap>", line 665, in _load_unlocked
  File "<frozen importlib._bootstrap_external>", line 678, in exec_module
  File "<frozen importlib._bootstrap>", line 219, in _call_with_frames_removed
  File "/home/nick/Bad_drivers/Bad_drivers/bad_drivers/registration/urls.py", line 4, in <module>
    from .views import UserProfileListCreateView, UserProfileDetailView, UserProfileUpdate
  File "/home/nick/Bad_drivers/Bad_drivers/bad_drivers/registration/views.py", line 21
    def list(self, request):
                           ^
IndentationError: unindent does not match any outer indentation level

/home/nick/Bad_drivers/Bad_drivers/bad_drivers/registration/views.py changed, reloading.
Performing system checks...

Watching for file changes with StatReloader
Exception in thread django-main-thread:
Traceback (most recent call last):
  File "/usr/lib/python3.6/threading.py", line 916, in _bootstrap_inner
    self.run()
  File "/usr/lib/python3.6/threading.py", line 864, in run
    self._target(*self._args, **self._kwargs)
  File "/home/nick/Bad_drivers/Bad_drivers/env/lib/python3.6/site-packages/django/utils/autoreload.py", line 53, in wrapper
    fn(*args, **kwargs)
  File "/home/nick/Bad_drivers/Bad_drivers/env/lib/python3.6/site-packages/django/core/management/commands/runserver.py", line 118, in inner_run
    self.check(display_num_errors=True)
  File "/home/nick/Bad_drivers/Bad_drivers/env/lib/python3.6/site-packages/django/core/management/base.py", line 396, in check
    databases=databases,
  File "/home/nick/Bad_drivers/Bad_drivers/env/lib/python3.6/site-packages/django/core/checks/registry.py", line 70, in run_checks
    new_errors = check(app_configs=app_configs, databases=databases)
  File "/home/nick/Bad_drivers/Bad_drivers/env/lib/python3.6/site-packages/django/core/checks/urls.py", line 13, in check_url_config
    return check_resolver(resolver)
  File "/home/nick/Bad_drivers/Bad_drivers/env/lib/python3.6/site-packages/django/core/checks/urls.py", line 23, in check_resolver
    return check_method()
  File "/home/nick/Bad_drivers/Bad_drivers/env/lib/python3.6/site-packages/django/urls/resolvers.py", line 408, in check
    for pattern in self.url_patterns:
  File "/home/nick/Bad_drivers/Bad_drivers/env/lib/python3.6/site-packages/django/utils/functional.py", line 48, in __get__
    res = instance.__dict__[self.name] = self.func(instance)
  File "/home/nick/Bad_drivers/Bad_drivers/env/lib/python3.6/site-packages/django/urls/resolvers.py", line 589, in url_patterns
    patterns = getattr(self.urlconf_module, "urlpatterns", self.urlconf_module)
  File "/home/nick/Bad_drivers/Bad_drivers/env/lib/python3.6/site-packages/django/utils/functional.py", line 48, in __get__
    res = instance.__dict__[self.name] = self.func(instance)
  File "/home/nick/Bad_drivers/Bad_drivers/env/lib/python3.6/site-packages/django/urls/resolvers.py", line 582, in urlconf_module
    return import_module(self.urlconf_name)
  File "/usr/lib/python3.6/importlib/__init__.py", line 126, in import_module
    return _bootstrap._gcd_import(name[level:], package, level)
  File "<frozen importlib._bootstrap>", line 994, in _gcd_import
  File "<frozen importlib._bootstrap>", line 971, in _find_and_load
  File "<frozen importlib._bootstrap>", line 955, in _find_and_load_unlocked
  File "<frozen importlib._bootstrap>", line 665, in _load_unlocked
  File "<frozen importlib._bootstrap_external>", line 678, in exec_module
  File "<frozen importlib._bootstrap>", line 219, in _call_with_frames_removed
  File "/home/nick/Bad_drivers/Bad_drivers/bad_drivers/bad_drivers/urls.py", line 28, in <module>
    path("registration/",include("registration.urls"))
  File "/home/nick/Bad_drivers/Bad_drivers/env/lib/python3.6/site-packages/django/urls/conf.py", line 34, in include
    urlconf_module = import_module(urlconf_module)
  File "/usr/lib/python3.6/importlib/__init__.py", line 126, in import_module
    return _bootstrap._gcd_import(name[level:], package, level)
  File "<frozen importlib._bootstrap>", line 994, in _gcd_import
  File "<frozen importlib._bootstrap>", line 971, in _find_and_load
  File "<frozen importlib._bootstrap>", line 955, in _find_and_load_unlocked
  File "<frozen importlib._bootstrap>", line 665, in _load_unlocked
  File "<frozen importlib._bootstrap_external>", line 678, in exec_module
  File "<frozen importlib._bootstrap>", line 219, in _call_with_frames_removed
  File "/home/nick/Bad_drivers/Bad_drivers/bad_drivers/registration/urls.py", line 4, in <module>
    from .views import UserProfileListCreateView, UserProfileDetailView, UserProfileUpdate
  File "/home/nick/Bad_drivers/Bad_drivers/bad_drivers/registration/views.py", line 21
    def list(self, request):
                           ^
IndentationError: unindent does not match any outer indentation level

/home/nick/Bad_drivers/Bad_drivers/bad_drivers/registration/views.py changed, reloading.
Performing system checks...

Watching for file changes with StatReloader
Exception in thread django-main-thread:
Traceback (most recent call last):
  File "/usr/lib/python3.6/threading.py", line 916, in _bootstrap_inner
    self.run()
  File "/usr/lib/python3.6/threading.py", line 864, in run
    self._target(*self._args, **self._kwargs)
  File "/home/nick/Bad_drivers/Bad_drivers/env/lib/python3.6/site-packages/django/utils/autoreload.py", line 53, in wrapper
    fn(*args, **kwargs)
  File "/home/nick/Bad_drivers/Bad_drivers/env/lib/python3.6/site-packages/django/core/management/commands/runserver.py", line 118, in inner_run
    self.check(display_num_errors=True)
  File "/home/nick/Bad_drivers/Bad_drivers/env/lib/python3.6/site-packages/django/core/management/base.py", line 396, in check
    databases=databases,
  File "/home/nick/Bad_drivers/Bad_drivers/env/lib/python3.6/site-packages/django/core/checks/registry.py", line 70, in run_checks
    new_errors = check(app_configs=app_configs, databases=databases)
  File "/home/nick/Bad_drivers/Bad_drivers/env/lib/python3.6/site-packages/django/core/checks/urls.py", line 13, in check_url_config
    return check_resolver(resolver)
  File "/home/nick/Bad_drivers/Bad_drivers/env/lib/python3.6/site-packages/django/core/checks/urls.py", line 23, in check_resolver
    return check_method()
  File "/home/nick/Bad_drivers/Bad_drivers/env/lib/python3.6/site-packages/django/urls/resolvers.py", line 408, in check
    for pattern in self.url_patterns:
  File "/home/nick/Bad_drivers/Bad_drivers/env/lib/python3.6/site-packages/django/utils/functional.py", line 48, in __get__
    res = instance.__dict__[self.name] = self.func(instance)
  File "/home/nick/Bad_drivers/Bad_drivers/env/lib/python3.6/site-packages/django/urls/resolvers.py", line 589, in url_patterns
    patterns = getattr(self.urlconf_module, "urlpatterns", self.urlconf_module)
  File "/home/nick/Bad_drivers/Bad_drivers/env/lib/python3.6/site-packages/django/utils/functional.py", line 48, in __get__
    res = instance.__dict__[self.name] = self.func(instance)
  File "/home/nick/Bad_drivers/Bad_drivers/env/lib/python3.6/site-packages/django/urls/resolvers.py", line 582, in urlconf_module
    return import_module(self.urlconf_name)
  File "/usr/lib/python3.6/importlib/__init__.py", line 126, in import_module
    return _bootstrap._gcd_import(name[level:], package, level)
  File "<frozen importlib._bootstrap>", line 994, in _gcd_import
  File "<frozen importlib._bootstrap>", line 971, in _find_and_load
  File "<frozen importlib._bootstrap>", line 955, in _find_and_load_unlocked
  File "<frozen importlib._bootstrap>", line 665, in _load_unlocked
  File "<frozen importlib._bootstrap_external>", line 678, in exec_module
  File "<frozen importlib._bootstrap>", line 219, in _call_with_frames_removed
  File "/home/nick/Bad_drivers/Bad_drivers/bad_drivers/bad_drivers/urls.py", line 28, in <module>
    path("registration/",include("registration.urls"))
  File "/home/nick/Bad_drivers/Bad_drivers/env/lib/python3.6/site-packages/django/urls/conf.py", line 34, in include
    urlconf_module = import_module(urlconf_module)
  File "/usr/lib/python3.6/importlib/__init__.py", line 126, in import_module
    return _bootstrap._gcd_import(name[level:], package, level)
  File "<frozen importlib._bootstrap>", line 994, in _gcd_import
  File "<frozen importlib._bootstrap>", line 971, in _find_and_load
  File "<frozen importlib._bootstrap>", line 955, in _find_and_load_unlocked
  File "<frozen importlib._bootstrap>", line 665, in _load_unlocked
  File "<frozen importlib._bootstrap_external>", line 678, in exec_module
  File "<frozen importlib._bootstrap>", line 219, in _call_with_frames_removed
  File "/home/nick/Bad_drivers/Bad_drivers/bad_drivers/registration/urls.py", line 4, in <module>
    from .views import UserProfileListCreateView, UserProfileDetailView, UserProfileUpdate
  File "/home/nick/Bad_drivers/Bad_drivers/bad_drivers/registration/views.py", line 21
    def list(self, request):
                           ^
IndentationError: unindent does not match any outer indentation level

/home/nick/Bad_drivers/Bad_drivers/bad_drivers/registration/views.py changed, reloading.
Performing system checks...

Watching for file changes with StatReloader
Exception in thread django-main-thread:
Traceback (most recent call last):
  File "/usr/lib/python3.6/threading.py", line 916, in _bootstrap_inner
    self.run()
  File "/usr/lib/python3.6/threading.py", line 864, in run
    self._target(*self._args, **self._kwargs)
  File "/home/nick/Bad_drivers/Bad_drivers/env/lib/python3.6/site-packages/django/utils/autoreload.py", line 53, in wrapper
    fn(*args, **kwargs)
  File "/home/nick/Bad_drivers/Bad_drivers/env/lib/python3.6/site-packages/django/core/management/commands/runserver.py", line 118, in inner_run
    self.check(display_num_errors=True)
  File "/home/nick/Bad_drivers/Bad_drivers/env/lib/python3.6/site-packages/django/core/management/base.py", line 396, in check
    databases=databases,
  File "/home/nick/Bad_drivers/Bad_drivers/env/lib/python3.6/site-packages/django/core/checks/registry.py", line 70, in run_checks
    new_errors = check(app_configs=app_configs, databases=databases)
  File "/home/nick/Bad_drivers/Bad_drivers/env/lib/python3.6/site-packages/django/core/checks/urls.py", line 13, in check_url_config
    return check_resolver(resolver)
  File "/home/nick/Bad_drivers/Bad_drivers/env/lib/python3.6/site-packages/django/core/checks/urls.py", line 23, in check_resolver
    return check_method()
  File "/home/nick/Bad_drivers/Bad_drivers/env/lib/python3.6/site-packages/django/urls/resolvers.py", line 408, in check
    for pattern in self.url_patterns:
  File "/home/nick/Bad_drivers/Bad_drivers/env/lib/python3.6/site-packages/django/utils/functional.py", line 48, in __get__
    res = instance.__dict__[self.name] = self.func(instance)
  File "/home/nick/Bad_drivers/Bad_drivers/env/lib/python3.6/site-packages/django/urls/resolvers.py", line 589, in url_patterns
    patterns = getattr(self.urlconf_module, "urlpatterns", self.urlconf_module)
  File "/home/nick/Bad_drivers/Bad_drivers/env/lib/python3.6/site-packages/django/utils/functional.py", line 48, in __get__
    res = instance.__dict__[self.name] = self.func(instance)
  File "/home/nick/Bad_drivers/Bad_drivers/env/lib/python3.6/site-packages/django/urls/resolvers.py", line 582, in urlconf_module
    return import_module(self.urlconf_name)
  File "/usr/lib/python3.6/importlib/__init__.py", line 126, in import_module
    return _bootstrap._gcd_import(name[level:], package, level)
  File "<frozen importlib._bootstrap>", line 994, in _gcd_import
  File "<frozen importlib._bootstrap>", line 971, in _find_and_load
  File "<frozen importlib._bootstrap>", line 955, in _find_and_load_unlocked
  File "<frozen importlib._bootstrap>", line 665, in _load_unlocked
  File "<frozen importlib._bootstrap_external>", line 678, in exec_module
  File "<frozen importlib._bootstrap>", line 219, in _call_with_frames_removed
  File "/home/nick/Bad_drivers/Bad_drivers/bad_drivers/bad_drivers/urls.py", line 28, in <module>
    path("registration/",include("registration.urls"))
  File "/home/nick/Bad_drivers/Bad_drivers/env/lib/python3.6/site-packages/django/urls/conf.py", line 34, in include
    urlconf_module = import_module(urlconf_module)
  File "/usr/lib/python3.6/importlib/__init__.py", line 126, in import_module
    return _bootstrap._gcd_import(name[level:], package, level)
  File "<frozen importlib._bootstrap>", line 994, in _gcd_import
  File "<frozen importlib._bootstrap>", line 971, in _find_and_load
  File "<frozen importlib._bootstrap>", line 955, in _find_and_load_unlocked
  File "<frozen importlib._bootstrap>", line 665, in _load_unlocked
  File "<frozen importlib._bootstrap_external>", line 678, in exec_module
  File "<frozen importlib._bootstrap>", line 219, in _call_with_frames_removed
  File "/home/nick/Bad_drivers/Bad_drivers/bad_drivers/registration/urls.py", line 4, in <module>
    from .views import UserProfileListCreateView, UserProfileDetailView, UserProfileUpdate
  File "/home/nick/Bad_drivers/Bad_drivers/bad_drivers/registration/views.py", line 21
    def list(self, request):
                           ^
IndentationError: unindent does not match any outer indentation level

/home/nick/Bad_drivers/Bad_drivers/bad_drivers/registration/views.py changed, reloading.
Performing system checks...

Watching for file changes with StatReloader
